Workbook

Sheet Master
A1: Test Document: Assessment 8 - Final Project
I2: Tested
A3: Total Tests | B3: =SUM(D3:G3) -> 124 | C3: Total Tests | D3: ='Unit Testing'!B2 -> 37 | E3: =IE!B2 -> 37 | F3: =Phone!B2 -> 18 | G3: =Tablet!B2 -> 32 | I3: In Progress
A4: Tested | B4: =SUM(D4:G4) -> 124 | C4: Tested | D4: ='Unit Testing'!B3 -> 37 | E4: =IE!B3 -> 37 | F4: =Phone!B3 -> 18 | G4: =Tablet!B3 -> 32 | I4: Not Tested
A5: % Complete | B5: =B4/B3 -> 1 | C5: % Complete | D5: =D4/D3 -> 1 | E5: =E4/E3 -> 1 | F5: =F4/F3 -> 1 | G5: =G4/G3 -> 1 | I5: Error
D6: Browser Type (tested on laptop) | F6: Device Type/Screen size
A7: Test | B7: Test ID | C7: Comments | D7: Unit Testing (Chrome) | E7: IE | F7: Phone | G7: Tablet | H7: Plesk
A8: Login | B8: AD.1 | D8: ='Unit Testing'!D8 -> Tested | E8: =IE!D8 -> Tested | F8: n/a | G8: =Tablet!D8 -> Tested | H8: =Plesk!D8 -> Tested
A9: Login - not registered | B9: AD.2 | D9: ='Unit Testing'!D9 -> Tested | E9: =IE!D9 -> Tested | F9: n/a | G9: n/a | H9: n/a
A10: Logout | B10: AD.3 | D10: ='Unit Testing'!D10 -> Tested | E10: =IE!D10 -> Tested | F10: n/a | G10: =Tablet!D9 -> Tested | H10: =Plesk!D9 -> Tested
A11: Attempt to access cakes page directly | B11: AD.4 | D11: ='Unit Testing'!D11 -> Tested | E11: =IE!D11 -> Tested | F11: n/a | G11: n/a | H11: n/a
A12: Display cakes | B12: AD.5 | D12: ='Unit Testing'!D12 -> Tested | E12: =IE!D12 -> Tested | F12: n/a | G12: =Tablet!D10 -> Tested | H12: =Plesk!D10 -> Tested
A13: Update cake - cancel | B13: AD.6.1 | D13: ='Unit Testing'!D13 -> Tested | E13: =IE!D13 -> Tested | F13: n/a | G13: n/a | H13: n/a
A14: Update cake | B14: AD.6.2 | D14: ='Unit Testing'!D14 -> Tested | E14: =IE!D14 -> Tested | F14: n/a | G14: =Tablet!D11 -> Tested | H14: =Plesk!D11 -> Tested
A15: Add cake - cancel | B15: AD.7.1 | D15: ='Unit Testing'!D15 -> Tested | E15: =IE!D15 -> Tested | F15: n/a | G15: n/a | H15: n/a
A16: Add cake | B16: AD.7.2 | D16: ='Unit Testing'!D16 -> Tested | E16: =IE!D16 -> Tested | F16: n/a | G16: =Tablet!D12 -> Tested | H16: =Plesk!D12 -> Tested
A17: Delete cake - cancel | B17: AD.8.1 | D17: ='Unit Testing'!D17 -> Tested | E17: =IE!D17 -> Tested | F17: n/a | G17: n/a | H17: n/a
A18: Delete cake | B18: AD.8.2 | D18: ='Unit Testing'!D18 -> Tested | E18: =IE!D18 -> Tested | F18: n/a | G18: =Tablet!D13 -> Tested | H18: =Plesk!D13 -> Tested
A19: Add cake images | B19: AD.9 | D19: ='Unit Testing'!D19 -> Tested | E19: =IE!D19 -> Tested | F19: n/a | G19: =Tablet!D14 -> Tested | H19: =Plesk!D14 -> Tested
A20: Delete cake images | B20: AD.10 | D20: ='Unit Testing'!D20 -> Tested | E20: =IE!D20 -> Tested | F20: n/a | G20: =Tablet!D15 -> Tested | H20: =Plesk!D15 -> Tested
A21: Display testimonials | B21: AD.11 | D21: ='Unit Testing'!D21 -> Tested | E21: =IE!D21 -> Tested | F21: n/a | G21: =Tablet!D16 -> Tested | H21: =Plesk!D16 -> Tested
A22: Add testimonial | B22: AD.12 | D22: ='Unit Testing'!D22 -> Tested | E22: =IE!D22 -> Tested | F22: n/a | G22: =Tablet!D17 -> Tested | H22: =Plesk!D17 -> Tested
A23: Delete testimonial | B23: AD.13 | D23: ='Unit Testing'!D23 -> Tested | E23: =IE!D23 -> Tested | F23: n/a | G23: =Tablet!D18 -> Tested | H23: =Plesk!D18 -> Tested
A24: Udpate company info | B24: AD.14 | D24: ='Unit Testing'!D24 -> Tested | E24: =IE!D24 -> Tested | F24: n/a | G24: =Tablet!D19 -> Tested | H24: =Plesk!D19 -> Tested
A25: Add user | B25: AD.15 | D25: ='Unit Testing'!D25 -> Tested | E25: =IE!D25 -> Tested | F25: n/a | G25: =Tablet!D20 -> Tested | H25: =Plesk!D20 -> Tested
A26: Delete user | B26: AD.16 | D26: ='Unit Testing'!D26 -> Tested | E26: =IE!D26 -> Tested | F26: n/a | G26: =Tablet!D21 -> Tested | H26: =Plesk!D21 -> Tested
A27: Home - menu | B27: PUB.1 | D27: ='Unit Testing'!D27 -> Tested | E27: =IE!D27 -> Tested | F27: =Phone!D8 -> Tested | G27: =Tablet!D22 -> Tested | H27: =Plesk!D22 -> Tested
A28: Home - body | B28: PUB.2 | D28: ='Unit Testing'!D28 -> Tested | E28: =IE!D28 -> Tested | F28: =Phone!D9 -> Tested | G28: =Tablet!D23 -> Tested | H28: =Plesk!D23 -> Tested
A29: Home - footer | B29: PUB.3 | D29: ='Unit Testing'!D29 -> Tested | E29: =IE!D29 -> Tested | F29: =Phone!D10 -> Tested | G29: =Tablet!D24 -> Tested | H29: =Plesk!D24 -> Tested
A30: Cakes - menu | B30: PUB.4 | D30: ='Unit Testing'!D30 -> Tested | E30: =IE!D30 -> Tested | F30: =Phone!D11 -> Tested | G30: =Tablet!D25 -> Tested | H30: =Plesk!D25 -> Tested
A31: Cakes - body | B31: PUB.5 | D31: ='Unit Testing'!D31 -> Tested | E31: =IE!D31 -> Tested | F31: =Phone!D12 -> Tested | G31: =Tablet!D26 -> Tested | H31: =Plesk!D26 -> Tested
A32: Cakes - footer | B32: PUB.6 | D32: ='Unit Testing'!D32 -> Tested | E32: =IE!D32 -> Tested | F32: =Phone!D13 -> Tested | G32: =Tablet!D27 -> Tested | H32: =Plesk!D27 -> Tested
A33: Cake Category - menu | B33: PUB.7 | D33: ='Unit Testing'!D33 -> Tested | E33: =IE!D33 -> Tested | F33: =Phone!D14 -> Tested | G33: =Tablet!D28 -> Tested | H33: =Plesk!D28 -> Tested
A34: Cake Category - body | B34: PUB.8 | D34: ='Unit Testing'!D34 -> Tested | E34: =IE!D34 -> Tested | F34: =Phone!D15 -> Tested | G34: =Tablet!D29 -> Tested | H34: =Plesk!D29 -> Tested
A35: Cake Category - footer | B35: PUB.9 | D35: ='Unit Testing'!D35 -> Tested | E35: =IE!D35 -> Tested | F35: =Phone!D16 -> Tested | G35: =Tablet!D30 -> Tested | H35: =Plesk!D30 -> Tested
A36: Single Cake - menu | B36: PUB.10 | D36: ='Unit Testing'!D36 -> Tested | E36: =IE!D36 -> Tested | F36: =Phone!D17 -> Tested | G36: =Tablet!D31 -> Tested | H36: =Plesk!D31 -> Tested
A37: Single Cake - body | B37: PUB.11 | D37: ='Unit Testing'!D37 -> Tested | E37: =IE!D37 -> Tested | F37: =Phone!D18 -> Tested | G37: =Tablet!D32 -> Tested | H37: =Plesk!D32 -> Tested
A38: Single Cake - footer | B38: PUB.12 | D38: ='Unit Testing'!D38 -> Tested | E38: =IE!D38 -> Tested | F38: =Phone!D19 -> Tested | G38: =Tablet!D33 -> Tested | H38: =Plesk!D33 -> Tested
... A42: Contact - menu | B42: PUB.16 | D42: ='Unit Testing'!D42 -> Tested | E42: =IE!D42 -> Tested | F42: =Phone!D23 -> Tested | G42: =Tablet!D37 -> Tested | H42: =Plesk!D37 -> Tested
A43: Contact - body | B43: PUB.17 | C43: Submit only works on plesk | D43: ='Unit Testing'!D43 -> Tested | E43: =IE!D43 -> Tested | F43: =Phone!D24 -> Tested | G43: =Tablet!D38 -> Tested | H43: =Plesk!D38 -> Tested
...

Sheet Unit Testing
A1: Unit Testing
A2: Total Tests: | B2: =SUM(E8:E56) -> 37 | D2: Tested
A3: Tested: | B3: =SUM(F8:F56) -> 37 | D3: In Progress
A4: % Complete: | B4: =B3/B2 -> 1 | D4: Not Tested
D5: Error
A7: Test | B7: Test Case | C7: Test Scenario/Pre-requisite | D7: Status | E7: Tests to complete | F7: Complete = 1 Incomplete = 0 | G7: Test Steps | H7: Test Data | I7: Expected Result | J7: Actual Result
A8: Login | B8: AD.1 | C8: User created in database | D8: Tested | E8: 1 | F8: 1 | G8: 1. Insert URL: http://localhost/a8/ppcakes/admin/index.php 2. Enter email address 3. Enter password 4. Select login button | H8: Email: admin@ppcakes Password: admin123 | I8: User is presented with login page. User is presented with a_cakes page upon successful login. Administrator menu bar appears: Cakes, Testimonials, Company Info, Users & Logout button. | J8: As expected
A9: Login - not registered | B9: AD.2 | C9: User not created in database | D9: Tested | E9: 1 | F9: 1 | G9: 1. Insert URL: http://localhost/a8/ppcakes/admin/index.php 2. Enter email address 3. Enter password 4. Select login button | H9: Email: admin@pickles Password: admin123 | I9: User is presented with login page. Error message is given for unknown user. | J9: As expected
A10: Logout | B10: AD.3 | C10: User is logged in | D10: Tested | E10: 1 | F10: 1 | G10: 1. Select logout button | H10: Test logout button from the following admin pages: a_cakes cake_create cake_update image_upload testim testim_create coinfo users user_create | I10: User is logged out from page and returned to admin index/login page. | J10: As expected
A11: Attempt to access cakes page directly | B11: AD.4 | C11: User is not logged in | D11: Tested | E11: 1 | F11: 1 | G11: 1. Insert URL: http://localhost/a8/ppcakes/admin/php/a_cakes.php | H11: Refer test steps | I11: User is directed to login page. | J11: As expected
A12: Display cakes | B12: AD.5 | C12: User is logged in | D12: Tested | E12: 1 | F12: 1 | G12: 1. Login 2. Review information displayed is as per information in database | H12: Refer to screenshots | I12: Data from database is displayed in correct place on the webpage. Correct category description is displayed. | J12: As expected
A13: Update cake - cancel | B13: AD.6.1 | C13: User is logged in | D13: Tested | E13: 1 | F13: 1 | G13: 1. Select pencil icon in action column 2. Update cake details 3. Select Back to List or Cancel button. | H13: Refer to screenshots | I13: Changes are not saved | J13: As expected
A14: Update cake | B14: AD.6.2 | C14: User is logged in | D14: Tested | E14: 1 | F14: 1 | G14: 1. Select pencil icon in action column 2. Update cake details, drop down list and free text 3. Select Save Changes button. | H14: Update category from Birthday to Wedding. Update flavours from Chocolate, Vanilla, Lemon to Chocolate Mud. | I14: Changes are updated and shown in cakes screen user is redirected back to cakes page. | J14: As expected
A15: Add cake - cancel | B15: AD.7.1 | C15: User is logged in | D15: Tested | E15: 1 | F15: 1 | G15: 1. Select + New Cake button 2. Add cake details, drop down list and free text 3. Select Cancel button | H15: Refer to screenshots | I15: Changes are not saved, user is redirected back to cakes page. | J15: As expected
A16: Add cake | B16: AD.7.2 | C16: User is logged in | D16: Tested | E16: 1 | F16: 1 | G16: 1. Select + New Cake button 2. Add cake details, drop down list and free text 3. Select Add Cake button. | H16: Refer to screenshots | I16: Changes are saved and new cake is shown in cakes screen user is redirected to upload images page. | J16: As expected
A17: Delete cake - cancel | B17: AD.8.1 | C17: User is logged in | D17: Tested | E17: 1 | F17: 1 | G17: 1. Select trash icon in action column 2. Select no to confirm | H17: Refer to screenshots | I17: User is returned to cakes page, cake is not deleted. | J17: As expected
A18: Delete cake | B18: AD.8.2 | C18: User is logged in | D18: Tested | E18: 1 | F18: 1 | G18: 1. Select trash icon in action column 2. Select yes to confirm | H18: Refer to screenshots | I18: User is returned to cakes page, cake and images are deleted from database tables. | J18: As expected
A19: Add cake images | B19: AD.9 | C19: User is logged in | D19: Tested | E19: 1 | F19: 1 | G19: 1. Select Choose file button 2. Select image 3. Select Upload image button 4. Select Back to List button | H19: Cake #16 Images: flower1, flower2 | I19: Image links are saved to database, images are moved to the images file, images appear for cake on webpage. | J19: Error: Oops! Something went wrong. Please try again later. Solution: Added delete stament for images table as well.
... A44: Contact - footer | B44: PUB.18 | C44: Footer | D44: Tested | E44: 1 | F44: 1 | G44: 1. Check footer displays (functionality as per all pages as footer is an external php page) | H44: n/a | I44: Footer displays correctly. Refer to test UT.PUB.3 for test results. | J44: As expected

Sheet IE
A1: Functional Testing: Internet Explorer - Standard laptop
A2: Total Tests: | B2: =SUM(E8:E97) -> 37 | D2: Tested
A3: Tested: | B3: =SUM(F8:F97) -> 37 | D3: In Progress
A4: % Complete: | B4: =B3/B2 -> 1 | D4: Not Tested
D5: Error
A7: Page | B7: Test Case | C7: Test | D7: Status | E7: Tests to complete | F7: Complete = 1 Incomplete = 0 | G7: Test Steps | H7: Test Data | I7: Expected Result | J7: Actual Result
A8: Login | B8: AD.1 | C8: User created in database | D8: Tested | E8: 1 | F8: 1 | G8: 1. Insert URL: http://localhost/a8/ppcakes/admin/index.php 2. Enter email address 3. Enter password 4. Select login button | H8: Email: admin@ppcakes Password: admin123 | I8: User is presented with login page. User is presented with a_cakes page upon successful login. Administrator menu bar appears: Cakes, Testimonials, Company Info, Users & Logout button. | J8: As expected
A9: Login - not registered | B9: AD.2 | C9: User not created in database | D9: Tested | E9: 1 | F9: 1 | G9: 1. Insert URL: http://localhost/a8/ppcakes/admin/index.php 2. Enter email address 3. Enter password 4. Select login button | H9: Email: admin@pickles Password: admin123 | I9: User is presented with login page. Error message is given for unknown user. | J9: As expected
A10: Logout | B10: AD.3 | C10: User is logged in | D10: Tested | E10: 1 | F10: 1 | G10: 1. Select logout button | H10: Test logout button from the following admin pages: a_cakes cake_create cake_update image_upload testim testim_create coinfo users user_create | I10: User is logged out from page and returned to admin index/login page. | J10: As expected
A11: Attempt to access cakes page directly | B11: AD.4 | C11: User is not logged in | D11: Tested | E11: 1 | F11: 1 | G11: 1. Insert URL: http://localhost/a8/ppcakes/admin/php/a_cakes.php | H11: Refer test steps | I11: User is directed to login page. | J11: As expected
A12: Display cakes | B12: AD.5 | C12: User is logged in | D12: Tested | E12: 1 | F12: 1 | G12: 1. Login 2. Review information displayed is as per information in database | I12: Data from database is displayed in correct place on the webpage. Correct category description is displayed. | J12: As expected
A13: Update cake - cancel | B13: AD.6.1 | C13: User is logged in | D13: Tested | E13: 1 | F13: 1 | G13: 1. Select pencil icon in action column 2. Update cake details 3. Select Back to List or Cancel button. | I13: Changes are not saved | J13: As expected
A14: Update cake | B14: AD.6.2 | C14: User is logged in | D14: Tested | E14: 1 | F14: 1 | G14: 1. Select pencil icon in action column 2. Update cake details, drop down list and free text 3. Select Save Changes button. | H14: Update category from Birthday to Wedding. Update flavours from Chocolate, Vanilla, Lemon to Chocolate Mud. | I14: Changes are updated and shown in cakes screen user is redirected back to cakes page. | J14: As expected
A15: Add cake - cancel | B15: AD.7.1 | C15: User is logged in | D15: Tested | E15: 1 | F15: 1 | G15: 1. Select + New Cake button 2. Add cake details, drop down list and free text 3. Select Cancel button | I15: Changes are not saved, user is redirected back to cakes page. | J15: As expected
A16: Add cake | B16: AD.7.2 | C16: User is logged in | D16: Tested | E16: 1 | F16: 1 | G16: 1. Select + New Cake button 2. Add cake details, drop down list and free text 3. Select Add Cake button. | H16: Birthday Test Cake Test Cake Test Cake Test Cake | I16: Changes are saved and new cake is shown in cakes screen user is redirected to upload images page. | J16: As expected
A17: Delete cake - cancel | B17: AD.8.1 | C17: User is logged in | D17: Tested | E17: 1 | F17: 1 | G17: 1. Select trash icon in action column 2. Select no to confirm | I17: User is returned to cakes page, cake is not deleted. | J17: As expected
A18: Delete cake | B18: AD.8.2 | C18: User is logged in | D18: Tested | E18: 1 | F18: 1 | G18: 1. Select trash icon in action column 2. Select yes to confirm | I18: User is returned to cakes page, cake and images are deleted from database tables. | J18: As expected
A19: Add cake images | B19: AD.9 | C19: User is logged in | D19: Tested | E19: 1 | F19: 1 | G19: 1. Select Choose file button 2. Select image 3. Select Upload image button 4. Select Back to List button | H19: Cake #25, created in test AD.7.2 | I19: Image links are saved to database, images are moved to the images file, images appear for cake on webpage. | J19: Screen displays differently to chrome - see screenshots
A20: Delete cake images | B20: AD.10 | C20: User is logged in | D20: Tested | E20: 1 | F20: 1 | G20: 1. Select picture icon in action column 2. Select Delete Image button | H20: Cake #16 Image: flower2 | I20: Selected image is deleted from database and images folder, all other images remain. | J20: As expected
A21: Display testimonials | B21: AD.11 | C21: User is logged in | D21: Tested | E21: 1 | F21: 1 | G21: 1. Select Testimonials from menu | I21: All testimonials are displayed | J21: As expected
A22: Add testimonial | B22: AD.12 | C22: User is logged in | D22: Tested | E22: 1 | F22: 1 | G22: 1. Select + New Testimonial button 2. Enter text 3. Select Create Entry button | I22: Testimonial is created in data base, displays on testimonial page | J22: As expected
A23: Delete testimonial | B23: AD.13 | C23: User is logged in | D23: Tested | E23: 1 | F23: 1 | G23: 1. Select trash icon in action column 2. Select yes to confirm | I23: User is returned to testimonial page, testimonial no longer displays, is deleted from database table. | J23: As expected
A24: Udpate company info | B24: AD.14 | C24: User is logged in | D24: Tested | E24: 1 | F24: 1 | G24: 1. Select Company Info from menu | H24: Added XYZ to phone, email, location, facebook, instagram, cake page heading and description | I24: Records are updated and user redirected to Cakes landing page. | J24: As expected
A25: Add user | B25: AD.15 | C25: User is logged in | D25: Tested | E25: 1 | F25: 1 | G25: 1. Select Users from menu 2. Select + New User button 3. Enter user details 4. Logout 5. Log back in as new user | I25: User list is diplayed initially. New user is created, user can log in and access admin menu. | J25: As expected
A26: Delete user | B26: AD.16 | C26: User is logged in | D26: Tested | E26: 1 | F26: 1 | G26: 1. Select trash icon in action column 2. Select yes to confirm | H26: Name: New User, from UT.AD.15 | I26: User is deleted from database and cannot log in. | J26: As expected
A27: Home - menu | B27: PUB.1 | C27: Menu bar | D27: Tested | E27: 1 | F27: 1 | G27: 1. open URL: http://localhost/a8/ppcakes/index.php 2. Click on each menu item | I27: Selecting menu item should go to respective page. Selecting Logo should stay on page. Active page should be in bold. Hovering over menu should change text colour and create shadow. | J27: As expected
A28: Home - body | B28: PUB.2 | C28: Body | D28: Tested | E28: 1 | F28: 1 | G28: 1. Review layout | I28: Main image should be clear. Should be a contrast to page body. Should have a shadow. Tagline should be clear and transparent, aligned to the top right of the image. Image should scroll with the page. | J28: As expected
A29: Home - footer | B29: PUB.3 | C29: Footer | D29: Tested | E29: 1 | F29: 1 | G29: 1. Check footer displays 2. Select social media icons | I29: Footer text is centered, with social icons to the right. Hovering over social icons should animate them. Clicking in the icons should open a new page and take user to respective web page. | J29: As expected
A30: Cakes - menu | B30: PUB.4 | C30: Menu bar | D30: Tested | E30: 1 | F30: 1 | G30: 1. Click on each menu item | I30: Selecting menu item should go to respective page. Selecting Logo should go to home page. Active page should be in bold. Hovering over menu should change text colour and create shadow. | J30: As expected
A31: Cakes - body | B31: PUB.5 | C31: Body | D31: Tested | E31: 1 | F31: 1 | G31: 1. Review layout | I31: Title and paragraph text should come from database table. An image and title should display for each category. Clicking on an image should take the user to the page for the category selected. | J31: As expected
A32: Cakes - footer | B32: PUB.6 | C32: Footer | D32: Tested | E32: 1 | F32: 1 | G32: 1. Check footer displays (functionality as per all pages as footer is an external php page) | H32: n/a | I32: Footer displays correctly. Refer to test UT.PUB.3 for test results. | J32: As expected
A33: Cake Category - menu | B33: PUB.7 | C33: Menu bar | D33: Tested | E33: 1 | F33: 1 | G33: 1. Click on each menu item | I33: Selecting menu item should go to respective page. Selecting Logo should go to home page. Active page should be in bold. Hovering over menu should change text colour and create shadow. | J33: As expected
A34: Cake Category - body | B34: PUB.8 | C34: Body | D34: Tested | E34: 1 | F34: 1 | G34: 1. Review layout | I34: Title and paragraph text should come from database table. Each cake should show once, with an image. | J34: As expected
A35: Cake Category - footer | B35: PUB.9 | C35: Footer | D35: Tested | E35: 1 | F35: 1 | G35: 1. Check footer displays (functionality as per all pages as footer is an external php page) | H35: n/a | I35: Footer displays correctly. Refer to test UT.PUB.3 for test results. | J35: As expected
A36: Single Cake - menu | B36: PUB.10 | C36: Menu bar | D36: Tested | E36: 1 | F36: 1 | G36: 1. Click on each menu item | I36: Selecting menu item should go to respective page. Selecting Logo should go to home page. Active page should be in bold. Hovering over menu should change text colour and create shadow. | J36: As expected
A37: Single Cake - body | B37: PUB.11 | C37: Body | D37: Tested | E37: 1 | F37: 1 | G37: 1. Review layout | I37: Title paragraph text should come from database table. Images should carousel through themselves. Send message button should go to contact page.
A38: Single Cake - footer | B38: PUB.12 | C38: Footer | D38: Tested | E38: 1 | F38: 1 | G38: 1. Check footer displays (functionality as per all pages as footer is an external php page) | H38: n/a | I38: Footer displays correctly. Refer to test UT.PUB.3 for test results. | J38: As expected
A39: About - menu | B39: PUB.13 | C39: Menu bar | D39: Tested | E39: 1 | F39: 1 | G39: 1. Click on each menu item | I39: Selecting menu item should go to respective page. Selecting Logo should go to home page. Active page should be in bold. Hovering over menu should change text colour and create shadow. | J39: As expected
A40: About - body | B40: PUB.14 | C40: Body | D40: Tested | E40: 1 | F40: 1 | G40: 1. Review layout | I40: Title and paragraph text should come from database table. All testimonials should display from database table. | J40: Error: Testimonials display with one word per line. Solution: page was missing a </div> tag
A41: About - footer | B41: PUB.15 | C41: Footer | D41: Tested | E41: 1 | F41: 1 | G41: 1. Check footer displays (functionality as per all pages as footer is an external php page) | H41: n/a | I41: Footer displays correctly. Refer to test UT.PUB.3 for test results. | J41: As expected
...

Sheet Phone
A1: Functional Testing: Phone
A2: Total Tests: | B2: =SUM(E8:E42) -> 18 | D2: Tested
A3: Tested: | B3: =SUM(F8:F42) -> 18 | D3: In Progress
A4: % Complete: | B4: =B3/B2 -> 1 | D4: Not Tested
D5: Error
A7: Page | B7: Test Case | C7: Test | D7: Status | E7: Tests to complete | F7: Complete = 1 Incomplete = 0 | G7: Test Steps | H7: Test Data | I7: Expected Result | J7: Portrait result (375 x 667) | K7: Landscape result (667 x 375)
A8: Home - menu | B8: PUB.1 | C8: Menu bar | D8: Tested | E8: 1 | F8: 1 | G8: 1. open URL: http://localhost/a8/ppcakes/index.php 2. Click on each menu item | H8: Refer to screen shots | I8: Selecting menu item should go to respective page. Selecting Logo should stay on page. Selecting mobile menu should invoke menu list panel. Active page should be in red text. | J8: Issue: Mobile menu is not aligned to the right side. Solution: Added padding-top: 1rem, padding-left: 1rem. py-sm-3 px-sm-3 (for @media min-width: 576px) | K8: Issue: Mobile menu is not aligned to the right side. Solution: Added padding-top: 1rem, padding-left: 1rem. py-md-3 px-sm-3 (for @media min-width: 768px)
A9: Home - body | B9: PUB.2 | C9: Body | D9: Tested | E9: 1 | F9: 1 | G9: 1. Review layout | H9: Refer to screen shots | I9: Main image should be clear. Should be a contrast to page body. Should have a shadow. Tagline should be clear and transparent, aligned to the top right of the image. Image should scroll with the page. | J9: As expected | K9: As expected
A10: Home - footer | B10: PUB.3 | C10: Footer | D10: Tested | E10: 1 | F10: 1 | G10: 1. Check footer displays 2. Select social media icons | H10: Refer to screen shots | I10: All Footer text is centered. Clicking social media icons should take user to respective web page. | J10: As expected | K10: As expected
A11: Cakes - menu | B11: PUB.4 | C11: Menu bar | D11: Tested | E11: 1 | F11: 1 | G11: 1. Click on each menu item | H11: Refer to screen shots | I11: Selecting menu item should go to respective page. Selecting Logo should go to home page. Active page should be in bold. Hovering over menu should change text colour and create shadow. | J11: Refer test PUB.1 | K11: Refer test PUB.1
A12: Cakes - body | B12: PUB.5 | C12: Body | D12: Tested | E12: 1 | F12: 1 | G12: 1. Review layout | H12: Refer to screen shots | I12: Title and paragraph text should come from database table. An image and title should display for each category. Clicking on an image should take the user to the page for the category selected. | J12: Padding needs to increase above page title. | K12: Padding needs to increase above page title.
A13: Cakes - footer | B13: PUB.6 | C13: Footer | D13: Tested | E13: 1 | F13: 1 | G13: 1. Check footer displays (functionality as per all pages as footer is an external php page) | H13: n/a | I13: Footer displays correctly. Refer to test UT.PUB.3 for test results. | J13: As expected | K13: As expected
A14: Cake Category - menu | B14: PUB.7 | C14: Menu bar | D14: Tested | E14: 1 | F14: 1 | G14: 1. Click on each menu item | H14: Refer to screen shots | I14: Selecting menu item should go to respective page. Selecting Logo should go to home page. Active page should be in bold. Hovering over menu should change text colour and create shadow. | J14: Refer test PUB.1 | K14: Refer test PUB.1
A15: Cake Category - body | B15: PUB.8 | C15: Body | D15: Tested | E15: 1 | F15: 1 | G15: 1. Review layout | H15: Refer to screen shots | I15: Title and paragraph text should come from database table. Each cake should show once, with an image. | J15: Refer test PUB.5 | K15: Refer test PUB.5
A16: Cake Category - footer | B16: PUB.9 | C16: Footer | D16: Tested | E16: 1 | F16: 1 | G16: 1. Check footer displays (functionality as per all pages as footer is an external php page) | H16: n/a | I16: Footer displays correctly. Refer to test UT.PUB.3 for test results. | J16: As expected | K16: As expected
A17: Single Cake - menu | B17: PUB.10 | C17: Menu bar | D17: Tested | E17: 1 | F17: 1 | G17: 1. Click on each menu item | H17: Refer to screen shots | I17: Selecting menu item should go to respective page. Selecting Logo should go to home page. Active page should be in bold. Hovering over menu should change text colour and create shadow. | J17: Refer test PUB.1 | K17: Refer test PUB.1
A18: Single Cake - body | B18: PUB.11 | C18: Body | D18: Tested | E18: 1 | F18: 1 | G18: 1. Review layout | H18: Refer to screen shots | I18: Title paragraph text should come from database table. Images should carousel through themselves. Send message button should go to contact page. | J18: As expected | K18: As expected
A19: Single Cake - footer | B19: PUB.12 | C19: Footer | D19: Tested | E19: 1 | F19: 1 | G19: 1. Check footer displays (functionality as per all pages as footer is an external php page) | H19: n/a | I19: Footer displays correctly. Refer to test UT.PUB.3 for test results. | J19: As expected | K19: As expected
... A25: Contact - footer | B25: PUB.18 | C25: Footer | D25: Tested | E25: 1 | F25: 1 | G25: 1. Check footer displays (functionality as per all pages as footer is an external php page) | H25: n/a | I25: Footer displays correctly. Refer to test UT.PUB.3 for test results. | J25: As expected | K25: As expected

Sheet Tablet
A1: Functional Testing: Tablet
A2: Total Tests: | B2: =SUM(E8:E93) -> 32 | D2: Tested
A3: Tested: | B3: =SUM(F8:F93) -> 32 | D3: In Progress
A4: % Complete: | B4: =B3/B2 -> 1 | D4: Not Tested
D5: Error
A7: Page | B7: Test Case | C7: Test | D7: Status | E7: Tests to complete | F7: Complete = 1 Incomplete = 0 | G7: Test Steps | H7: Test Data | I7: Expected Result | J7: Portrait result (768 x 1024) | K7: Landscape result (1024 x 768)
A8: Login | B8: AD.1 | C8: User created in database | D8: Tested | E8: 1 | F8: 1 | G8: 1. Insert URL: http://localhost/a8/ppcakes/admin/index.php 2. Enter email address 3. Enter password 4. Select login button | H8: Email: admin@ppcakes Password: admin123 | I8: User is presented with login page. User is presented with a_cakes page upon successful login. Administrator menu bar appears: Cakes, Testimonials, Company Info, Users & Logout button. | J8: Issue: Mobile menu appears but shouldnt. Solution: Remove mobile menu references from page | K8: As expected
A9: Logout | B9: AD.3 | C9: User is logged in | D9: Tested | E9: 1 | F9: 1 | G9: 1. Select logout button | H9: Test logout button from the following admin pages: a_cakes cake_create cake_update image_upload testim testim_create coinfo users user_create | I9: User is logged out from page and returned to admin index/login page. | J9: As expected | K9: As expected
A10: Display cakes | B10: AD.5 | C10: User is logged in | D10: Tested | E10: 1 | F10: 1 | G10: 1. Login 2. Review information displayed is as per information in database | H10: Refer to screenshots | I10: Data from database is displayed in correct place on the webpage. Correct category description is displayed. | J10: Issue: Table width outside of container. Title too close to top. Solution: added <br> to move trash icon to 2nd line. Added padding to first row. | K10: As expected
A11: Update cake | B11: AD.6.2 | C11: User is logged in | D11: Tested | E11: 1 | F11: 1 | G11: 1. Select pencil icon in action column 2. Update cake details, drop down list and free text 3. Select Save Changes button. | H11: Update category from Birthday to Wedding. Update flavours from Chocolate, Vanilla, Lemon to Chocolate Mud. | I11: Changes are updated and shown in cakes screen user is redirected back to cakes page. | J11: Issue: Title too close to top. Save changes and Cancel buttons stacked ontop of each other - should be spead apart. Solution: Added padding to first row. Removed "lg" from column sizing | K11: As expected
A12: Add cake | B12: AD.7.2 | C12: User is logged in | D12: Tested | E12: 1 | F12: 1 | G12: 1. Select + New Cake button 2. Add cake details, drop down list and free text 3. Select Add Cake button. | H12: Refer to screenshots | I12: Changes are saved and new cake is shown in cakes screen user is redirected to upload images page. | J12: Issue: Title too close to top. Save changes and Cancel buttons stacked ontop of each other - should be spead apart. Solution: Added padding to first row. Removed "lg" from column sizing | K12: As expected
A13: Delete cake | B13: AD.8.2 | C13: User is logged in | D13: Tested | E13: 1 | F13: 1 | G13: 1. Select trash icon in action column 2. Select yes to confirm | H13: Refer to screenshots | I13: User is returned to cakes page, cake and images are deleted from database tables. | J13: As expected | K13: As expected
A14: Add cake images | B14: AD.9 | C14: User is logged in | D14: Tested | E14: 1 | F14: 1 | G14: 1. Select Choose file button 2. Select image 3. Select Upload image button 4. Select Back to List button | H14: Cake #16 Images: flower1, flower2 | I14: Image links are saved to database, images are moved to the images file, images appear for cake on webpage. | J14: Issue: Title too close to top. Solution: Added padding to first row. Removed "lg" from column sizing. | K14: As expected
A15: Delete cake images | B15: AD.10 | C15: User is logged in | D15: Tested | E15: 1 | F15: 1 | G15: 1. Select picture icon in action column 2. Select Delete Image button | H15: Cake #16 Image: flower1 | I15: Selected image is deleted from database and images folder, all other images remain. | J15: As expected | K15: As expected
A16: Display testimonials | B16: AD.11 | C16: User is logged in | D16: Tested | E16: 1 | F16: 1 | G16: 1. Select Testimonials from menu | H16: Refer to screenshots | I16: All testimonials are displayed | J16: Issue: Title too close to top, button on next line, menu missing. Solution: Added padding to first row. Removed "lg" from column sizing. Added menu updates. | K16: As expected
A17: Add testimonial | B17: AD.12 | C17: User is logged in | D17: Tested | E17: 1 | F17: 1 | G17: 1. Select + New Testimonial button 2. Enter text 3. Select Create Entry button | H17: Refer to screenshots | I17: Testimonial is created in data base, displays on testimonial page | J17: Issue: Title too close to top, button on next line, menu missing. Solution: Added padding to first row. Removed "lg" from column sizing. Added menu updates. | K17: As expected
A18: Delete testimonial | B18: AD.13 | C18: User is logged in | D18: Tested | E18: 1 | F18: 1 | G18: 1. Select trash icon in action column 2. Select yes to confirm | H18: Refer to screenshots | I18: User is returned to testimonial page, testimonial no longer displays, is deleted from database table. | J18: As expected | K18: As expected
A19: Udpate company info | B19: AD.14 | C19: User is logged in | D19: Tested | E19: 1 | F19: 1 | G19: 1. Select Company Info from menu | H19: Added XYZ to phone, email, location, facebook, instagram, cake page heading and description | I19: Records are updated and user redirected to Cakes landing page. | J19: Issue: Menu missing. Update and Cancel buttons stacked ontop of each other - should be spead apart. Solution: Added menu updates. Removed "lg" from column sizing for button section. | K19: As expected
A20: Add user | B20: AD.15 | C20: User is logged in | D20: Tested | E20: 1 | F20: 1 | G20: 1. Select Users from menu 2. Select + New User button 3. Enter user details 4. Logout 5. Log back in as new user | H20: Refer to screenshots, password: newbie123 | I20: User list is diplayed initially. New user is created, user can log in and access admin menu. | J20: Issue: Title too close to top, button on next line, menu missing. Solution: Added padding to first row. Removed "lg" from column sizing. Added menu updates.
A21: Delete user | B21: AD.16 | C21: User is logged in | D21: Tested | E21: 1 | F21: 1 | G21: 1. Select trash icon in action column 2. Select yes to confirm | H21: Name: New User, from UT.AD.15 | I21: User is deleted from database and cannot log in. | J21: As expected | K21: As expected
A22: Home - menu | B22: PUB.1 | C22: Menu bar | D22: Tested | E22: 1 | F22: 1 | G22: 1. open URL: http://localhost/a8/ppcakes/index.php 2. Click on each menu item | H22: Refer to screen shots | I22: Selecting menu item should go to respective page. Selecting Logo should stay on page. Active page should be in bold. Hovering over menu should change text colour and create shadow. | J22: Selecting menu item goes to respective page. Selecting Logo should stays page. Selecting mobile menu invokes menu list panel. Active page is in red text. | K22: As expected
A23: Home - body | B23: PUB.2 | C23: Body | D23: Tested | E23: 1 | F23: 1 | G23: 1. Review layout | H23: Refer to screen shots | I23: Main image should be clear. Should be a contrast to page body. Should have a shadow. Tagline should be clear and transparent, aligned to the top right of the image. Image should scroll with the page. | J23: As expected | K23: As expected
A24: Home - footer | B24: PUB.3 | C24: Footer | D24: Tested | E24: 1 | F24: 1 | G24: 1. Check footer displays 2. Select social media icons | H24: Refer to screen shots | I24: Footer text is centered, with social icons to the right. Hovering over social icons should animate them. Clicking in the isons should open a new page and take user to respective web page.
A25: Cakes - menu | B25: PUB.4 | C25: Menu bar | D25: Tested | E25: 1 | F25: 1 | G25: 1. Click on each menu item | H25: Refer to screen shots | I25: Selecting menu item should go to respective page. Selecting Logo should go to home page. Active page should be in bold. Hovering over menu should change text colour and create shadow. | J25: Refer test PUB.1 | K25: Refer test PUB.1
A26: Cakes - body | B26: PUB.5 | C26: Body | D26: Tested | E26: 1 | F26: 1 | G26: 1. Review layout | H26: Refer to screen shots | I26: Title and paragraph text should come from database table. An image and title should display for each category. Clicking on an image should take the user to the page for the category selected. | J26: As expected | K26: As expected
A27: Cakes - footer | B27: PUB.6 | C27: Footer | D27: Tested | E27: 1 | F27: 1 | G27: 1. Check footer displays (functionality as per all pages as footer is an external php page) | H27: n/a | I27: Footer displays correctly. Refer to test UT.PUB.3 for test results. | J27: Refer to test PUB.3 | K27: Refer to test PUB.3
A28: Cake Category - menu | B28: PUB.7 | C28: Menu bar | D28: Tested | E28: 1 | F28: 1 | G28: 1. Click on each menu item | H28: Refer to screen shots | I28: Selecting menu item should go to respective page. Selecting Logo should go to home page. Active page should be in bold. Hovering over menu should change text colour and create shadow. | J28: Refer test PUB.1 | K28: Refer test PUB.1
A29: Cake Category - body | B29: PUB.8 | C29: Body | D29: Tested | E29: 1 | F29: 1 | G29: 1. Review layout | H29: Refer to screen shots | I29: Title and paragraph text should come from database table. Each cake should show once, with an image. | J29: Issue: Images overlap container. Solution: Updated "col-md-3" to "col-md-4 col-lg-3" | K29: As expected
A30: Cake Category - footer | B30: PUB.9 | C30: Footer | D30: Tested | E30: 1 | F30: 1 | G30: 1. Check footer displays (functionality as per all pages as footer is an external php page) | H30: n/a | I30: Footer displays correctly. Refer to test UT.PUB.3 for test results. | J30: Refer to test PUB.3 | K30: Refer to test PUB.3
A31: Single Cake - menu | B31: PUB.10 | C31: Menu bar | D31: Tested | E31: 1 | F31: 1 | G31: 1. Click on each menu item | H31: Refer to screen shots | I31: Selecting menu item should go to respective page. Selecting Logo should go to home page. Active page should be in bold. Hovering over menu should change text colour and create shadow. | J31: Refer test PUB.1 | K31: Refer test PUB.1
A32: Single Cake - body | B32: PUB.11 | C32: Body | D32: Tested | E32: 1 | F32: 1 | G32: 1. Review layout | H32: Refer to screen shots | I32: Title paragraph text should come from database table. Images should carousel through themselves. Send message button should go to contact page. | J32: As expected | K32: As expected
A33: Single Cake - footer | B33: PUB.12 | C33: Footer | D33: Tested | E33: 1 | F33: 1 | G33: 1. Check footer displays (functionality as per all pages as footer is an external php page) | H33: n/a | I33: Footer displays correctly. Refer to test UT.PUB.3 for test results. | J33: Refer to test PUB.3 | K33: Refer to test PUB.3
A34: About - menu | B34: PUB.13 | C34: Menu bar | D34: Tested | E34: 1 | F34: 1 | G34: 1. Click on each menu item | H34: Refer to screen shots | I34: Selecting menu item should go to respective page. Selecting Logo should go to home page. Active page should be in bold. Hovering over menu should change text colour and create shadow. | J34: Refer test PUB.1 | K34: Refer test PUB.1
A35: About - body | B35: PUB.14 | C35: Body | D35: Tested | E35: 1 | F35: 1 | G35: 1. Review layout | H35: Refer to screen shots | I35: Title and paragraph text should come from database table. All testimonials should display from database table. | J35: Issue: Main image and text are not aligned - too much padding above text Solution: Updated padding for blurb | K35: As expected
A36: About - footer | B36: PUB.15 | C36: Footer | D36: Tested | E36: 1 | F36: 1 | G36: 1. Check footer displays (functionality as per all pages as footer is an external php page) | H36: n/a | I36: Footer displays correctly. Refer to test UT.PUB.3 for test results. | J36: Refer to test PUB.3 | K36: Refer to test PUB.3
... A39: Contact - footer | B39: PUB.18 | C39: Footer | D39: Tested | E39: 1 | F39: 1 | G39: 1. Check footer displays (functionality as per all pages as footer is an external php page) | H39: n/a | I39: Footer displays correctly. Refer to test UT.PUB.3 for test results. | J39: Refer to test PUB.3 | K39: Refer to test PUB.3

Sheet Plesk
A1: Plesk
A2: Total Tests: | B2: =SUM(E8:E93) -> 32 | D2: Tested
A3: Tested: | B3: =SUM(F8:F93) -> 32 | D3: In Progress
A4: % Complete: | B4: =B3/B2 -> 1 | D4: Not Tested
D5: Error
A7: Page | B7: Test Case | C7: Test | D7: Status | E7: Tests to complete | F7: Complete = 1 Incomplete = 0 | G7: Test Steps | H7: Expected Result | I7: Actual Result
A8: Login | B8: AD.1 | C8: User created in database | D8: Tested | E8: 1 | F8: 1 | G8: 1. Insert URL: http://localhost/a8/ppcakes/admin/index.php 2. Enter email address 3. Enter password 4. Select login button | H8: User is presented with login page. User is presented with a_cakes page upon successful login. Administrator menu bar appears: Cakes, Testimonials, Company Info, Users & Logout button. | I8: As expected
A9: Logout | B9: AD.3 | C9: User is logged in | D9: Tested | E9: 1 | F9: 1 | G9: 1. Select logout button | H9: User is logged out from page and returned to admin index/login page. | I9: As expected
A10: Display cakes | B10: AD.5 | C10: User is logged in | D10: Tested | E10: 1 | F10: 1 | G10: 1. Login 2. Review information displayed is as per information in database | H10: Data from database is displayed in correct place on the webpage. Correct category description is displayed. | I10: As expected
A11: Update cake | B11: AD.6.2 | C11: User is logged in | D11: Tested | E11: 1 | F11: 1 | G11: 1. Select pencil icon in action column 2. Update cake details, drop down list and free text 3. Select Save Changes button. | H11: Changes are updated and shown in cakes screen user is redirected back to cakes page. | I11: As expected
A12: Add cake | B12: AD.7.2 | C12: User is logged in | D12: Tested | E12: 1 | F12: 1 | G12: 1. Select + New Cake button 2. Add cake details, drop down list and free text 3. Select Add Cake button. | H12: Changes are saved and new cake is shown in cakes screen user is redirected to upload images page. | I12: As expected
A13: Delete cake | B13: AD.8.2 | C13: User is logged in | D13: Tested | E13: 1 | F13: 1 | G13: 1. Select trash icon in action column 2. Select yes to confirm | H13: User is returned to cakes page, cake and images are deleted from database tables. | I13: As expected
A14: Add cake images | B14: AD.9 | C14: User is logged in | D14: Tested | E14: 1 | F14: 1 | G14: 1. Select Choose file button 2. Select image 3. Select Upload image button 4. Select Back to List button | H14: Image links are saved to database, images are moved to the images file, images appear for cake on webpage. | I14: As expected
A15: Delete cake images | B15: AD.10 | C15: User is logged in | D15: Tested | E15: 1 | F15: 1 | G15: 1. Select picture icon in action column 2. Select Delete Image button | H15: Selected image is deleted from database and images folder, all other images remain. | I15: As expected
A16: Display testimonials | B16: AD.11 | C16: User is logged in | D16: Tested | E16: 1 | F16: 1 | G16: 1. Select Testimonials from menu | H16: All testimonials are displayed | I16: Issue: ' translated to question mark on screen display (refer screenshot below) Solution: removed ' from text
A17: Add testimonial | B17: AD.12 | C17: User is logged in | D17: Tested | E17: 1 | F17: 1 | G17: 1. Select + New Testimonial button 2. Enter text 3. Select Create Entry button | H17: Testimonial is created in data base, displays on testimonial page | I17: As expected
A18: Delete testimonial | B18: AD.13 | C18: User is logged in | D18: Tested | E18: 1 | F18: 1 | G18: 1. Select trash icon in action column 2. Select yes to confirm | H18: User is returned to testimonial page, testimonial no longer displays, is deleted from database table. | I18: As expected
A19: Udpate company info | B19: AD.14 | C19: User is logged in | D19: Tested | E19: 1 | F19: 1 | G19: 1. Select Company Info from menu | H19: Records are updated and user redirected to Cakes landing page. | I19: As expected
... A39: Contact - footer | B39: PUB.18 | C39: Footer | D39: Tested | E39: 1 | F39: 1 | G39: 1. Check footer displays (functionality as per all pages as footer is an external php page) | H39: Footer displays correctly. Refer to test UT.PUB.3 for test results. | I39: As expected
A41: Testimonial text issue:
A62: Contact Form email content:
A63: Test1 | G63: Final output
A82: Success message/landing page
